<?xml version="1.0"?>
<!-- =================================================================================== -->
<!-- |    This document was autogenerated by xacro from
/root/ros/integration_ws/src/rr100_ur_description/urdf/rr100_ur.urdf.xacro | -->
<!-- |    EDITING THIS FILE BY HAND IS NOT RECOMMENDED                                 | -->
<!-- =================================================================================== -->
<robot name="chassis">
    <!-- Elevated value -->
    <!-- <xacro:property name="plate_thickness" value="0.40" />  -->
    <!-- Base footprint is on the ground under the robot -->
    <link name="base_footprint">
        <inertial>
            <origin rpy="0 0 0" xyz="0 0 0" />
            <mass value=".1" />
            <inertia ixx="0.010609" ixy="0" ixz="0" iyy="0.050409" iyz="0" izz="0.05865" />
        </inertial>
    </link>
    <!-- Base link is the center of the robot's bottom plate -->
    <link name="base_link">
        <inertial>
            <origin rpy="0 0 0" xyz="0 0 0" />
            <mass value=".1" />
            <inertia ixx="0.010609" ixy="0" ixz="0" iyy="0.050409" iyz="0" izz="0.05865" />
        </inertial>
        <visual>
            <origin rpy="0 -1.570795 0" xyz="0.03 0 -0.1" />
            <geometry>
                <mesh filename="package://rr100_description/meshes/rr100.dae"
                    scale="0.001 0.001 0.001" />
            </geometry>
            <material name="white">
                <color rgba="1 1 1 1.0" />
            </material>
        </visual>
        <collision>
            <origin rpy="0 -1.570795 0" xyz="0.03 0 -0.1" />
            <geometry>
                <mesh filename="package://rr100_description/meshes/rr100.dae"
                    scale="0.001 0.001 0.001" />
            </geometry>
        </collision>
    </link>
    <joint name="base_footprint_joint" type="fixed">
        <origin rpy="0 0 0" xyz="0 0 0.32075" />
        <parent link="base_footprint" />
        <child link="base_link" />
    </joint>
    <!-- Interial link stores the robot's inertial information -->
    <link name="inertial_link">
        <inertial>
            <mass value="120" />
            <origin xyz="0 0 0" />
            <inertia ixx="2.5606225" ixy="0" ixz="0" iyy="9.1726225" iyz="0" izz="8.18" />
        </inertial>
    </link>
    <joint name="inertial_joint" type="fixed">
        <origin rpy="0 0 0" xyz="0 0 0" />
        <parent link="base_link" />
        <child link="inertial_link" />
    </joint>
    <link name="front_left_steering">
        <visual>
            <origin rpy="0 0 0" xyz="0 -0.0 0" />
            <geometry>
                <box size="0.02 0.1 0.02" />
            </geometry>
            <material name="blue">
                <color rgba="0.2 0.2 0.6 1.0" />
            </material>
        </visual>
        <inertial>
            <mass value="5.0" />
            <origin xyz="0 -0.0 0" />
            <!--<inertia
      ixx="1.0" ixy="0" ixz="0"
                 iyy="1.0" iyz="0"
                 izz="1.0"/>-->
            <inertia ixx="0.008333333333333335" ixy="0" ixz="0" iyy="0.008333333333333335" iyz="0"
                izz="0.008333333333333335" />
        </inertial>
    </link>
    <joint name="front_left_steering_joint" type="revolute">
        <limit effort="10.0" lower="-0.57" upper="0.57" velocity="3.14" />
        <axis xyz="0 0 1" />
        <parent link="base_link" />
        <child link="front_left_steering" />
        <origin rpy="0 0 0" xyz="0.30 0.279 -0.11075" />
        <dynamics damping="0.7" />
    </joint>
    <link name="front_left_wheel_link">
        <inertial>
            <mass value="3.0" />
            <!-- <origin xyz="0 0 0" rpy="${M_PI/2}  0 0" /> -->
            <origin rpy="0  0 0" xyz="0 0 0" />
            <inertia ixx="0.035331249999999995" ixy="0" ixz="0" iyy="0.06615" iyz="0"
                izz="0.035331249999999995" />
        </inertial>
        <!-- <visual>
            <origin rpy="-1.570795  0 0" xyz="0 0 0" />
            <geometry>
                <cylinder length="0.095" radius="0.21" />
                <mesh filename="../meshes/left_front_wheel.obj" scale="3.75 3.75 2.75"/>
            </geometry>
            <material name="black">
                <color rgba="0 0 0 1" />
            </material>
        </visual> -->
        <collision>
            <origin rpy="1.570795 0 0" xyz="0 0 0" />
            <geometry>
                <cylinder length="0.095" radius="0.21" />
            </geometry>
            <material name="black">
                <color rgba="0 0 0 1" />
            </material>
        </collision>
    </link>
    <joint name="front_left_wheel" type="continuous">
        <!-- <limit effort="10.0" velocity="3.14" /> -->
        <parent link="front_left_steering" />
        <child link="front_left_wheel_link" />
        <origin rpy="0 0 0" xyz="0 0.0 0" />
        <axis rpy="0 0 0" xyz="0 1 0" />
    </joint>
    <link name="front_right_steering">
        <visual>
            <origin rpy="0 0 0" xyz="0 0.0 0" />
            <geometry>
                <box size="0.02 0.1 0.02" />
            </geometry>
            <material name="blue">
                <color rgba="0.2 0.2 0.6 1" />
            </material>
        </visual>
        <inertial>
            <mass value="5.0" />
            <origin xyz="0 0.0 0" />
            <!--<inertia
      ixx="1.0" ixy="0" ixz="0"
                 iyy="1.0" iyz="0"
                 izz="1.0"/>-->
            <inertia ixx="0.008333333333333335" ixy="0" ixz="0" iyy="0.008333333333333335" iyz="0"
                izz="0.008333333333333335" />
        </inertial>
    </link>
    <joint name="front_right_steering_joint" type="revolute">
        <limit effort="10.0" lower="-0.57" upper="0.57" velocity="3.14" />
        <axis xyz="0 0 1" />
        <parent link="base_link" />
        <child link="front_right_steering" />
        <origin rpy="0 0 0" xyz="0.30 -0.279 -0.11075" />
        <dynamics damping="0.7" />
    </joint>
    <link name="front_right_wheel_link">
        <!-- <contact>
            <lateral_friction value="1.0" />
            <rolling_friction value="1.0" />
            <stiffness value="30000" />
            <damping value="30000" />
        </contact> -->
        <inertial>
            <mass value="3.0" />
            <!-- <origin xyz="0 0 0" rpy="${M_PI/2}  0 0" />-->
            <origin rpy="0  0 0" xyz="0 0 0" />
            <inertia ixx="0.035331249999999995" ixy="0" ixz="0" iyy="0.06615" iyz="0"
                izz="0.035331249999999995" />
        </inertial>
        <!-- <visual>
            <origin rpy="1.570795  0 0" xyz="0 0 0" />
            <geometry>
                <mesh filename="../meshes/left_front_wheel.obj" scale="3.75 3.75 2.75"/>
                <cylinder length="0.095" radius="0.21" />
            </geometry>
            <material name="black">
                <color rgba="0 0 0 1" />
            </material>
        </visual> -->
        <collision>
            <origin rpy="1.570795 0 0" xyz="0 0 0" />
            <geometry>
                <cylinder length="0.095" radius="0.21" />
            </geometry>
            <material name="black">
                <color rgba="0 0 0 1" />
            </material>
        </collision>
    </link>
    <joint name="front_right_wheel" type="continuous">
        <parent link="front_right_steering" />
        <child link="front_right_wheel_link" />
        <origin rpy="0 0 0" xyz="0 -0.0 0" />
        <axis rpy="0 0 0" xyz="0 1 0" />
    </joint>
    <link name="rear_left_steering">
        <visual>
            <origin rpy="0 0 0" xyz="0 -0.0 0" />
            <geometry>
                <box size="0.02 0.1 0.02" />
            </geometry>
            <material name="blue">
                <color rgba="0.2 0.2 0.6 1" />
            </material>
        </visual>
        <inertial>
            <mass value="5.0" />
            <origin xyz="0 -0.0 0" />
            <!--<inertia
      ixx="1.0" ixy="0" ixz="0"
                 iyy="1.0" iyz="0"
                 izz="1.0"/>-->
            <inertia ixx="0.008333333333333335" ixy="0" ixz="0" iyy="0.008333333333333335" iyz="0"
                izz="0.008333333333333335" />
        </inertial>
    </link>
    <joint name="rear_left_steering_joint" type="revolute">
        <limit effort="10.0" lower="-0.57" upper="0.57" velocity="3.14" />
        <axis xyz="0 0 1" />
        <parent link="base_link" />
        <child link="rear_left_steering" />
        <origin rpy="0 0 0" xyz="-0.25 0.279 -0.11075" />
        <dynamics damping="0.7" />
    </joint>
    <link name="rear_left_wheel_link">
        <!-- <contact>
            <lateral_friction value="1.0" />
            <rolling_friction value="1.0" />
            <stiffness value="30000" />
            <damping value="30000" />
        </contact> -->
        <inertial>
            <mass value="3.0" />
            <!--         <origin xyz="0 0 0" rpy="${M_PI/2}  0 0" /> -->
            <origin rpy="0  0 0" xyz="0 0 0" />
            <inertia ixx="0.035331249999999995" ixy="0" ixz="0" iyy="0.06615" iyz="0"
                izz="0.035331249999999995" />
        </inertial>
        <!-- <visual>
            <origin rpy="-1.570795  0 0" xyz="0 0 0" />
            <geometry>
                <cylinder length="0.095" radius="0.21" />
                <mesh filename="../meshes/left_front_wheel.obj" scale="3.75 3.75 2.75"/>
            </geometry>
            <material name="black">
                <color rgba="0 0 0 1" />
            </material>
        </visual> -->
        <collision>
            <origin rpy="1.570795 0 0" xyz="0 0 0" />
            <geometry>
                <cylinder length="0.095" radius="0.21" />
            </geometry>
            <material name="black">
                <color rgba="0 0 0 1" />
            </material>
        </collision>
    </link>
    <joint name="rear_left_wheel" type="continuous">
        <parent link="rear_left_steering" />
        <child link="rear_left_wheel_link" />
        <origin rpy="0 0 0" xyz="0 0.0 0" />
        <axis rpy="0 0 0" xyz="0 1 0" />
    </joint>
    <link name="rear_right_steering">
        <visual>
            <origin rpy="0 0 0" xyz="0 0.0 0" />
            <geometry>
                <box size="0.02 0.1 0.02" />
            </geometry>
            <material name="blue">
                <color rgba="0.2 0.2 0.6 1" />
            </material>
        </visual>
        <inertial>
            <mass value="5.0" />
            <origin xyz="0 0.0 0" />
            <!--<inertia
      ixx="1.0" ixy="0" ixz="0"
                 iyy="1.0" iyz="0"
                 izz="1.0"/>-->
            <inertia ixx="0.008333333333333335" ixy="0" ixz="0" iyy="0.008333333333333335" iyz="0"
                izz="0.008333333333333335" />
        </inertial>
    </link>
    <joint name="rear_right_steering_joint" type="revolute">
        <limit effort="10.0" lower="-0.57" upper="0.57" velocity="3.14" />
        <axis xyz="0 0 1" />
        <parent link="base_link" />
        <child link="rear_right_steering" />
        <origin rpy="0 0 0" xyz="-0.25 -0.279 -0.11075" />
        <dynamics damping="0.7" />
    </joint>
    <link name="rear_right_wheel_link">
        <!-- <contact>
            <lateral_friction value="1.0" />
            <rolling_friction value="1.0" />
            <stiffness value="30000" />
            <damping value="30000" />
        </contact> -->
        <inertial>
            <mass value="3.0" />
            <!--         <origin xyz="0 0 0" rpy="${M_PI/2}  0 0" /> -->
            <origin rpy="0  0 0" xyz="0 0 0" />
            <inertia ixx="0.035331249999999995" ixy="0" ixz="0" iyy="0.06615" iyz="0"
                izz="0.035331249999999995" />
        </inertial>
        <!-- <visual>
            <origin rpy="1.570795  0 0" xyz="0 0 0" />
            <geometry>
                <mesh filename="../meshes/left_front_wheel.obj" scale="3.75 3.75 2.75"/>
                <cylinder length="0.095" radius="0.21" />
            </geometry>
            <material name="black">
                <color rgba="0 0 0 1" />
            </material>
        </visual> -->
        <collision>
            <origin rpy="1.570795 0 0" xyz="0 0 0" />
            <geometry>
                <cylinder length="0.095" radius="0.21" />
            </geometry>
            <material name="black">
                <color rgba="0 0 0 1" />
            </material>
        </collision>
    </link>
    <joint name="rear_right_wheel" type="continuous">
        <parent link="rear_right_steering" />
        <child link="rear_right_wheel_link" />
        <origin rpy="0 0 0" xyz="0 -0.0 0" />
        <axis rpy="0 0 0" xyz="0 1 0" />
    </joint>
</robot>