<?xml version="1.0"?>
<!-- =================================================================================== -->
<!-- |    This document was autogenerated by xacro from
/root/ros/integration_ws/src/rr100_ur_description/urdf/rr100_ur.urdf.xacro | -->
<!-- |    EDITING THIS FILE BY HAND IS NOT RECOMMENDED                                 | -->
<!-- =================================================================================== -->
<robot name="rr100">
    <link name="base_footprint">
        <inertial>
            <mass value="0.01" />
            <inertia ixx="0" ixy="0" ixz="0" iyy="0" iyz="0"
                izz="0" />
        </inertial>
    </link>
    <joint name="base_joint" type="fixed">
        <parent link="base_footprint" />
        <child link="base_link" />
        <origin xyz="0 0 0.32075" rpy="0 0 0" />
    </joint>
    <link name="base_link">
        <!-- <visual>
            <origin xyz="0 0 0.05" rpy="0 0 0" />
            <geometry>
                <box size="0.86 0.27 0.442" />
            </geometry>
            <material name="base_link-material">
                <color rgba="0.73 0.72 0.70 1" />
            </material>
        </visual>
        <visual>
            <origin xyz="0 0 0.24" rpy="0 0 0" />
            <geometry>
                <box size="0.89 0.404 0.069" />
            </geometry>
            <material name="base_link-material">
                <color rgba="0.32 0.318 0.3049 1" />
            </material>
        </visual>
        <visual>
            <origin xyz="0 0 0.34" rpy="0 0 0" />
            <geometry>
                <cylinder radius="0.07" length="0.142" />
            </geometry>
            <material name="base_link-material">
                <color rgba="0.0185 0.219 0.02 1" />
            </material>
        </visual> -->
        <visual>
            <origin rpy="0 -1.570795 0" xyz="0 0 -0.1" />
            <geometry>
                <mesh filename="package://rr100_description/meshes/rr100.dae"
                    scale="0.001 0.001 0.001" />
            </geometry>
            <material name="gray">
                <color rgba="0.7 0.7 0.7 1" />
            </material>
        </visual>
        <collision>
            <origin xyz="0 0 0.05" rpy="0 0 0" />
            <geometry>
                <box size="0.86 0.27 0.442" />
            </geometry>
        </collision>
        <collision>
            <origin xyz="0 0 0.24" rpy="0 0 0" />
            <geometry>
                <box size="0.89 0.404 0.069" />
            </geometry>
        </collision>
        <collision>
            <origin xyz="0 0 0.34" rpy="0 0 0" />
            <geometry>
                <cylinder radius="0.07" length="0.142" />
            </geometry>
        </collision>
        <inertial>
            <origin xyz="0 0 0" rpy="0 0 0" />
            <mass value="70" />
            <inertia ixx="11.666666666666666" ixy="0" ixz="0" iyy="11.666666666666666" iyz="0"
                izz="11.666666666666666" />
        </inertial>
    </link>
    <joint name="front_left_steering_joint" type="revolute">
        <parent link="base_link" />
        <child link="front_left_steering" />
        <origin xyz="0.25 0.275 -0.1" rpy="0 0 0" />
        <axis xyz="0 0 1" />
        <limit effort="1000.0" lower="-0.57" upper="0.57" velocity="0.5" />
    </joint>
    <link name="front_left_steering">
        <visual>
            <origin xyz="0 0 0" rpy="0 0 0" />
            <geometry>
                <box size="0.02 0.1 0.02" />
            </geometry>
            <material name="front_left_steering-material">
                <color rgba="0.010329823026364548 0.11443537381770343 0.45641102317066595 1" />
            </material>
        </visual>
        <inertial>
            <origin xyz="0 0 0" rpy="0 0 0" />
            <mass value="2" />
            <inertia ixx="0.3333333333333333" ixy="0" ixz="0" iyy="0.3333333333333333" iyz="0"
                izz="0.3333333333333333" />
        </inertial>
    </link>
    <joint name="front_left_wheel_joint" type="continuous">
        <parent link="front_left_steering" />
        <child link="front_left_wheel" />
        <origin xyz="0 0 0" rpy="-1.5707963267948963 0 0" />
        <axis xyz="0 0 1" />
    </joint>
    <link name="front_left_wheel">
        <visual>
            <origin xyz="0 0 0" rpy="0 0 0" />
            <geometry>
                <cylinder radius="0.21" length="0.095" />
            </geometry>
            <material name="front_left_wheel-material">
                <color rgba="0.10702310296918527 0.10946171076915331 0.3712376804636741 1" />
            </material>
        </visual>
        <collision>
            <origin xyz="0 0 0" rpy="0 0 0" />
            <geometry>
                <cylinder radius="0.21" length="0.095" />
            </geometry>
        </collision>
        <inertial>
            <origin xyz="0 0 0" rpy="0 0 0" />
            <mass value="3" />
            <inertia ixx="1" ixy="0" ixz="0" iyy="1.5" iyz="0" izz="1" />
        </inertial>
    </link>
    <joint name="front_right_steering_joint" type="revolute">
        <parent link="base_link" />
        <child link="front_right_steering" />
        <origin xyz="0.25 -0.275 -0.1" rpy="0 0 0" />
        <axis xyz="0 0 1" />
        <limit effort="1000.0" lower="-0.57" upper="0.57" velocity="0.5" />
    </joint>
    <link name="front_right_steering">
        <visual>
            <origin xyz="0 0 0" rpy="0 0 0" />
            <geometry>
                <box size="0.02 0.1 0.02" />
            </geometry>
            <material name="front_right_steering-material">
                <color rgba="0.010329823026364548 0.11443537381770343 0.45641102317066595 1" />
            </material>
        </visual>
        <inertial>
            <origin xyz="0 0 0" rpy="0 0 0" />
            <mass value="2" />
            <inertia ixx="0.3333333333333333" ixy="0" ixz="0" iyy="0.3333333333333333" iyz="0"
                izz="0.3333333333333333" />
        </inertial>
    </link>
    <joint name="front_right_wheel_joint" type="continuous">
        <parent link="front_right_steering" />
        <child link="front_right_wheel" />
        <origin xyz="0 0 0" rpy="-1.5707963267948963 0 0" />
        <axis xyz="0 0 1" />
    </joint>
    <link name="front_right_wheel">
        <visual>
            <origin xyz="0 0 0" rpy="0 0 0" />
            <geometry>
                <cylinder radius="0.21" length="0.095" />
            </geometry>
            <material name="front_right_wheel-material">
                <color rgba="0.7835377915215659 0.37626212298046485 0.0030352698352941175 1" />
            </material>
        </visual>
        <collision>
            <origin xyz="0 0 0" rpy="0 0 0" />
            <geometry>
                <cylinder radius="0.21" length="0.095" />
            </geometry>
        </collision>
        <inertial>
            <origin xyz="0 0 0" rpy="0 0 0" />
            <mass value="3" />
            <inertia ixx="1" ixy="0" ixz="0" iyy="1.5" iyz="0" izz="1" />
        </inertial>
    </link>
    <joint name="rear_left_steering_joint" type="revolute">
        <parent link="base_link" />
        <child link="rear_left_steering" />
        <origin xyz="-0.25 0.275 -0.1" rpy="0 0 0" />
        <axis xyz="0 0 1" />
        <limit effort="1000.0" lower="-0.57" upper="0.57" velocity="0.5" />
    </joint>
    <link name="rear_left_steering">
        <visual>
            <origin xyz="0 0 0" rpy="0 0 0" />
            <geometry>
                <box size="0.02 0.1 0.02" />
            </geometry>
            <material name="rear_left_steering-material">
                <color rgba="0.0103 0.114 0.456 1" />
            </material>
        </visual>
        <inertial>
            <origin xyz="0 0 0" rpy="0 0 0" />
            <mass value="2" />
            <inertia ixx="0.3333333333333333" ixy="0" ixz="0" iyy="0.3333333333333333" iyz="0"
                izz="0.3333333333333333" />
        </inertial>
    </link>
    <joint name="rear_left_wheel_joint" type="continuous">
        <parent link="rear_left_steering" />
        <child link="rear_left_wheel" />
        <origin xyz="0 0 0" rpy="-1.5707963267948963 0 0" />
        <axis xyz="0 0 1" />
    </joint>
    <link name="rear_left_wheel">
        <visual>
            <origin xyz="0 0 0" rpy="0 0 0" />
            <geometry>
                <cylinder radius="0.21" length="0.095" />
            </geometry>
            <material name="rear_left_wheel-material">
                <color rgba="0.107 0.109 0.37 1" />
            </material>
        </visual>
        <collision>
            <origin xyz="0 0 0" rpy="0 0 0" />
            <geometry>
                <cylinder radius="0.21" length="0.095" />
            </geometry>
        </collision>
        <inertial>
            <origin xyz="0 0 0" rpy="0 0 0" />
            <mass value="3" />
            <inertia ixx="1" ixy="0" ixz="0" iyy="1.5" iyz="0" izz="1" />
        </inertial>
    </link>
    <joint name="rear_right_steering_joint" type="revolute">
        <parent link="base_link" />
        <child link="rear_right_steering" />
        <origin xyz="-0.25 -0.275 -0.1" rpy="0 0 0" />
        <axis xyz="0 0 1" />
        <limit effort="1000.0" lower="-0.57" upper="0.57" velocity="0.5" />
    </joint>
    <link name="rear_right_steering">
        <visual>
            <origin xyz="0 0 0" rpy="0 0 0" />
            <geometry>
                <box size="0.02 0.1 0.02" />
            </geometry>
            <material name="rear_right_steering-material">
                <color rgba="0.010329823026364548 0.11443537381770343 0.45641102317066595 1" />
            </material>
        </visual>
        <inertial>
            <origin xyz="0 0 0" rpy="0 0 0" />
            <mass value="2" />
            <inertia ixx="0.3333333333333333" ixy="0" ixz="0" iyy="0.3333333333333333" iyz="0"
                izz="0.3333333333333333" />
        </inertial>
    </link>
    <joint name="rear_right_wheel_joint" type="continuous">
        <parent link="rear_right_steering" />
        <child link="rear_right_wheel" />
        <origin xyz="0 0 0" rpy="-1.5707963267948963 0 0" />
        <axis xyz="0 0 1" />
    </joint>
    <link name="rear_right_wheel">
        <visual>
            <origin xyz="0 0 0" rpy="0 0 0" />
            <geometry>
                <cylinder radius="0.21" length="0.095" />
            </geometry>
            <material name="rear_right_wheel-material">
                <color rgba="0.7835377915215659 0.37626212298046485 0.0030352698352941175 1" />
            </material>
        </visual>
        <collision>
            <origin xyz="0 0 0" rpy="0 0 0" />
            <geometry>
                <cylinder radius="0.21" length="0.095" />
            </geometry>
        </collision>
        <inertial>
            <origin xyz="0 0 0" rpy="0 0 0" />
            <mass value="3" />
            <inertia ixx="1" ixy="0" ixz="0" iyy="1.5" iyz="0" izz="1" />
        </inertial>
    </link>
    <joint name="base_link_to_rslidar" type="fixed">
        <parent link="base_link" />
        <child link="rslidar" />
        <origin xyz="0 0 0.45" rpy="0 0 0" />
    </joint>
    <link name="rslidar">
        <visual>
            <origin xyz="0 0 0" rpy="0 0 0" />
            <geometry>
                <cylinder radius="0.061" length="0.081" />
            </geometry>
            <material name="rslidar-material">
                <color rgba="0.28 0.0528 0.413 1" />
            </material>
        </visual>
        <collision>
            <origin xyz="0 0 0" rpy="0 0 0" />
            <geometry>
                <cylinder radius="0.061" length="0.081" />
            </geometry>
        </collision>
        <inertial>
            <origin xyz="0 0 0" rpy="0 0 0" />
            <mass value="0.87" />
            <inertia ixx="0.29" ixy="0" ixz="0" iyy="0.435" iyz="0" izz="0.29" />
        </inertial>
    </link>

    <!--
    Base UR robot series xacro macro.

    NOTE: this is NOT a URDF. It cannot directly be loaded by consumers
    expecting a flattened '.urdf' file. See the top-level '.xacro' for that
    (but note: that .xacro must still be processed by the xacro command).

    For use in '.launch' files: use one of the 'load_urX.launch' convenience
    launch files.

    This file models the base kinematic chain of a UR robot, which then gets
    parameterised by various configuration files to convert it into a UR3(e),
    UR5(e), UR10(e), UR16e, UR20 or UR30.

    NOTE: the default kinematic parameters (ie: link lengths, frame locations,
    offets, etc) do not correspond to any particular robot. They are defaults
    only. There WILL be non-zero offsets between the Forward Kinematics results
    in TF (ie: robot_state_publisher) and the values reported by the Teach
    Pendant.

    For accurate (and robot-specific) transforms, the 'kinematics_parameters_file'
    parameter MUST point to a .yaml file containing the appropriate values for
    the targetted robot.

    If using the UniversalRobots/Universal_Robots_ROS_Driver, follow the steps
    described in the readme of that repository to extract the kinematic
    calibration from the controller and generate the required .yaml file.

    Main author of the migration to yaml configs: Ludovic Delval.

    Contributors to previous versions (in no particular order):

     - Felix Messmer
     - Kelsey Hawkins
     - Wim Meeussen
     - Shaun Edwards
     - Nadia Hammoudeh Garcia
     - Dave Hershberger
     - G. vd. Hoorn
     - Philip Long
     - Dave Coleman
     - Miguel Prada
     - Mathias Luedtke
     - Marcel Schnirring
     - Felix von Drigalski
     - Felix Exner
     - Jimmy Da Silva
     - Ajit Krisshna N L
     - Muhammad Asif Rana
  -->
    <!--
    NOTE: the macro defined in this file is NOT part of the public API of this
          package. Users CANNOT rely on this file being available, or stored in
          this location. Nor can they rely on the existence of the macro.
  -->
    <!--
  Author: Cristian Beltran
-->
    <link name="mounting_base_link">
        <inertial>
            <mass value="0.1" />
            <inertia ixx="0.0" ixy="0.0" ixz="0.0" iyy="0.0" iyz="0.0" izz="0.0" />
        </inertial>
        <visual>
            <origin rpy="0 0 1.570795" xyz="0 0 0" />
            <geometry>
                <!-- Actual -->
                <mesh filename="package://rr100_ur_description/meshes/ur5_mounting_plate.stl"
                    scale="0.001 0.001 0.001" />
                <!-- Elevated -->
                <!-- <mesh
                filename="package://rr100_ur_description/meshes/ur5_mounting_plate_shifted.stl"
                    scale="0.001 0.001 0.04" /> -->
            </geometry>
            <material name="grey" />
        </visual>
        <collision>
            <origin rpy="0 0 1.570795" xyz="0 0 0" />
            <geometry>
                <!-- Actual -->
                <mesh filename="package://rr100_ur_description/meshes/ur5_mounting_plate.stl"
                    scale="0.001 0.001 0.001" />
                <!-- <box size="${plate_width} ${plate_height} ${plate_thickness}"/> -->
            </geometry>
        </collision>
    </link>
    <joint name="mounting_base_joint" type="fixed">
        <!-- ${-base_x_size/2 + 0.025 + 0.2 / 2} 0 ${base_z_size} -->
        <origin rpy="0 0 0" xyz="-0.25 0 0.29575" />
        <parent link="base_link" />
        <child link="mounting_base_link" />
    </joint>
    <!-- links: main serial chain -->
    <link name="ur_base_link">
        <inertial>
            <mass value="0.1" />
            <inertia ixx="0.0" ixy="0.0" ixz="0.0" iyy="0.0" iyz="0.0" izz="0.0" />
        </inertial>
    </link>
    <link name="ur_base_link_inertia">
        <visual>
            <origin rpy="0 0 3.141592653589793" xyz="0 0 0" />
            <geometry>
                <mesh filename="package://ur_description/meshes/ur5e/visual/base.dae" />
            </geometry>
            <material name="LightGrey">
                <color rgba="0.7 0.7 0.7 1.0" />
            </material>
        </visual>
        <collision>
            <origin rpy="0 0 3.141592653589793" xyz="0 0 0" />
            <geometry>
                <mesh filename="package://ur_description/meshes/ur5e/collision/base.stl" />
            </geometry>
        </collision>
        <inertial>
            <mass value="4.0" />
            <origin rpy="0 0 0" xyz="0 0 0" />
            <inertia ixx="0.00443333156" ixy="0.0" ixz="0.0" iyy="0.00443333156" iyz="0.0"
                izz="0.0072" />
        </inertial>
    </link>
    <link name="ur_shoulder_link">
        <visual>
            <origin rpy="0 0 3.141592653589793" xyz="0 0 0" />
            <geometry>
                <mesh filename="package://ur_description/meshes/ur5e/visual/shoulder.dae" />
            </geometry>
            <material name="LightGrey">
                <color rgba="0.7 0.7 0.7 1.0" />
            </material>
        </visual>
        <collision>
            <origin rpy="0 0 3.141592653589793" xyz="0 0 0" />
            <geometry>
                <mesh filename="package://ur_description/meshes/ur5e/collision/shoulder.stl" />
            </geometry>
        </collision>
        <inertial>
            <mass value="3.7" />
            <origin rpy="0 0 0" xyz="0 0 0" />
            <inertia ixx="0.010267495893" ixy="0.0" ixz="0.0" iyy="0.010267495893" iyz="0.0"
                izz="0.00666" />
        </inertial>
    </link>
    <link name="ur_upper_arm_link">
        <visual>
            <origin rpy="1.5707963267948966 0 -1.5707963267948966" xyz="0 0 0.138" />
            <geometry>
                <mesh filename="package://ur_description/meshes/ur5e/visual/upperarm.dae" />
            </geometry>
            <material name="LightGrey">
                <color rgba="0.7 0.7 0.7 1.0" />
            </material>
        </visual>
        <collision>
            <origin rpy="1.5707963267948966 0 -1.5707963267948966" xyz="0 0 0.138" />
            <geometry>
                <mesh filename="package://ur_description/meshes/ur5e/collision/upperarm.stl" />
            </geometry>
        </collision>
        <inertial>
            <mass value="8.393" />
            <origin rpy="0 1.5707963267948966 0" xyz="-0.2125 0.0 0.138" />
            <inertia ixx="0.1338857818623325" ixy="0.0" ixz="0.0" iyy="0.1338857818623325" iyz="0.0"
                izz="0.0151074" />
        </inertial>
    </link>
    <link name="ur_forearm_link">
        <visual>
            <origin rpy="1.5707963267948966 0 -1.5707963267948966" xyz="0 0 0.007" />
            <geometry>
                <mesh filename="package://ur_description/meshes/ur5e/visual/forearm.dae" />
            </geometry>
            <material name="LightGrey">
                <color rgba="0.7 0.7 0.7 1.0" />
            </material>
        </visual>
        <collision>
            <origin rpy="1.5707963267948966 0 -1.5707963267948966" xyz="0 0 0.007" />
            <geometry>
                <mesh filename="package://ur_description/meshes/ur5e/collision/forearm.stl" />
            </geometry>
        </collision>
        <inertial>
            <mass value="2.275" />
            <origin rpy="0 1.5707963267948966 0" xyz="-0.1961 0.0 0.007" />
            <inertia ixx="0.031209355099586295" ixy="0.0" ixz="0.0" iyy="0.031209355099586295"
                iyz="0.0"
                izz="0.004095" />
        </inertial>
    </link>
    <link name="ur_wrist_1_link">
        <visual>
            <!-- TODO: Move this to a parameter -->
            <origin rpy="1.5707963267948966 0 0" xyz="0 0 -0.127" />
            <geometry>
                <mesh filename="package://ur_description/meshes/ur5e/visual/wrist1.dae" />
            </geometry>
            <material name="LightGrey">
                <color rgba="0.7 0.7 0.7 1.0" />
            </material>
        </visual>
        <collision>
            <origin rpy="1.5707963267948966 0 0" xyz="0 0 -0.127" />
            <geometry>
                <mesh filename="package://ur_description/meshes/ur5e/collision/wrist1.stl" />
            </geometry>
        </collision>
        <inertial>
            <mass value="1.219" />
            <origin rpy="0 0 0" xyz="0 0 0" />
            <inertia ixx="0.0025598989760400002" ixy="0.0" ixz="0.0" iyy="0.0025598989760400002"
                iyz="0.0"
                izz="0.0021942" />
        </inertial>
    </link>
    <link name="ur_wrist_2_link">
        <visual>
            <origin rpy="0 0 0" xyz="0 0 -0.0997" />
            <geometry>
                <mesh filename="package://ur_description/meshes/ur5e/visual/wrist2.dae" />
            </geometry>
            <material name="LightGrey">
                <color rgba="0.7 0.7 0.7 1.0" />
            </material>
        </visual>
        <collision>
            <origin rpy="0 0 0" xyz="0 0 -0.0997" />
            <geometry>
                <mesh filename="package://ur_description/meshes/ur5e/collision/wrist2.stl" />
            </geometry>
        </collision>
        <inertial>
            <mass value="1.219" />
            <origin rpy="0 0 0" xyz="0 0 0" />
            <inertia ixx="0.0025598989760400002" ixy="0.0" ixz="0.0" iyy="0.0025598989760400002"
                iyz="0.0"
                izz="0.0021942" />
        </inertial>
    </link>
    <link name="ur_wrist_3_link">
        <visual>
            <origin rpy="1.5707963267948966 0 0" xyz="0 0 -0.0989" />
            <geometry>
                <mesh filename="package://ur_description/meshes/ur5e/visual/wrist3.dae" />
            </geometry>
            <material name="LightGrey">
                <color rgba="0.7 0.7 0.7 1.0" />
            </material>
        </visual>
        <collision>
            <origin rpy="1.5707963267948966 0 0" xyz="0 0 -0.0989" />
            <geometry>
                <mesh filename="package://ur_description/meshes/ur5e/collision/wrist3.stl" />
            </geometry>
        </collision>
        <inertial>
            <mass value="0.1879" />
            <origin rpy="0 0 0" xyz="0.0 0.0 -0.0229" />
            <inertia ixx="9.890410052167731e-05" ixy="0.0" ixz="0.0" iyy="9.890410052167731e-05"
                iyz="0.0"
                izz="0.0001321171875" />
        </inertial>
    </link>
    <!-- joints: main serial chain -->
    <joint name="ur_base_link-base_link_inertia" type="fixed">
        <parent link="ur_base_link" />
        <child link="ur_base_link_inertia" />
        <!-- 'base_link' is REP-103 aligned (so X+ forward), while the internal
           frames of the robot/controller have X+ pointing backwards.
           Use the joint between 'base_link' and 'base_link_inertia' (a dummy
           link/frame) to introduce the necessary rotation over Z (of pi rad).
      -->
        <origin rpy="0 0 3.141592653589793" xyz="0 0 0" />
    </joint>
    <joint name="ur_shoulder_pan_joint" type="revolute">
        <parent link="ur_base_link_inertia" />
        <child link="ur_shoulder_link" />
        <origin rpy="0 0 0" xyz="0 0 0.1625" />
        <axis xyz="0 0 1" />
        <limit effort="150.0" lower="1.5707963267948966" upper="4.014257279586958"
            velocity="3.141592653589793" />
        <dynamics damping="0" friction="0" />
    </joint>
    <joint name="ur_shoulder_lift_joint" type="revolute">
        <parent link="ur_shoulder_link" />
        <child link="ur_upper_arm_link" />
        <origin rpy="1.570796327 0 0" xyz="0 0 0" />
        <axis xyz="0 0 1" />
        <limit effort="150.0" lower="-2.530727415391778" upper="0.5235987755982988"
            velocity="3.141592653589793" />
        <dynamics damping="0" friction="0" />
    </joint>
    <joint name="ur_elbow_joint" type="revolute">
        <parent link="ur_upper_arm_link" />
        <child link="ur_forearm_link" />
        <origin rpy="0 0 0" xyz="-0.425 0 0" />
        <axis xyz="0 0 1" />
        <limit effort="150.0" lower="-3.141592653589793" upper="3.141592653589793"
            velocity="3.141592653589793" />
        <dynamics damping="0" friction="0" />
    </joint>
    <joint name="ur_wrist_1_joint" type="revolute">
        <parent link="ur_forearm_link" />
        <child link="ur_wrist_1_link" />
        <origin rpy="0 0 0" xyz="-0.3922 0 0.1333" />
        <axis xyz="0 0 1" />
        <limit effort="28.0" lower="-6.283185307179586" upper="6.283185307179586"
            velocity="3.141592653589793" />
        <dynamics damping="0" friction="0" />
    </joint>
    <joint name="ur_wrist_2_joint" type="revolute">
        <parent link="ur_wrist_1_link" />
        <child link="ur_wrist_2_link" />
        <origin rpy="1.570796327 0 0" xyz="0 -0.0997 -2.044881182297852e-11" />
        <axis xyz="0 0 1" />
        <limit effort="28.0" lower="-6.283185307179586" upper="6.283185307179586"
            velocity="3.141592653589793" />
        <dynamics damping="0" friction="0" />
    </joint>
    <joint name="ur_wrist_3_joint" type="revolute">
        <parent link="ur_wrist_2_link" />
        <child link="ur_wrist_3_link" />
        <origin rpy="1.570796326589793 3.141592653589793 3.141592653589793"
            xyz="0 0.0996 -2.042830148012698e-11" />
        <axis xyz="0 0 1" />
        <limit effort="28.0" lower="-6.283185307179586" upper="6.283185307179586"
            velocity="3.141592653589793" />
        <dynamics damping="0" friction="0" />
    </joint>
    <!-- ROS-Industrial 'base' frame: base_link to UR 'Base' Coordinates transform -->
    <link name="ur_base">

        <inertial>
            <mass value="0.1" />
            <inertia ixx="0.0" ixy="0.0" ixz="0.0" iyy="0.0" iyz="0.0" izz="0.0" />
        </inertial>

    </link>
    <joint name="ur_base_link-base_fixed_joint" type="fixed">
        <!-- Note the rotation over Z of pi radians: as base_link is REP-103
           aligned (ie: has X+ forward, Y+ left and Z+ up), this is needed
           to correctly align 'base' with the 'Base' coordinate system of
           the UR controller.
      -->
        <origin rpy="0 0 3.141592653589793" xyz="0 0 0" />
        <parent link="ur_base_link" />
        <child link="ur_base" />
    </joint>
    <!-- ROS-Industrial 'flange' frame: attachment point for EEF models -->
    <link name="ur_flange">
        <inertial>
            <mass value="0.1" />
            <inertia ixx="0.0" ixy="0.0" ixz="0.0" iyy="0.0" iyz="0.0" izz="0.0" />
        </inertial>
    </link>
    <joint name="ur_wrist_3-flange" type="fixed">
        <parent link="ur_wrist_3_link" />
        <child link="ur_flange" />
        <origin rpy="0 -1.5707963267948966 -1.5707963267948966" xyz="0 0 0" />
    </joint>
    <!-- ROS-Industrial 'tool0' frame: all-zeros tool frame -->
    <link name="ur_tool0">
        <inertial>
            <mass value="0.1" />
            <inertia ixx="0.0" ixy="0.0" ixz="0.0" iyy="0.0" iyz="0.0" izz="0.0" />
        </inertial>
    </link>
    <joint name="ur_flange-tool0" type="fixed">
        <!-- default toolframe: X+ left, Y+ up, Z+ front -->
        <origin rpy="1.5707963267948966 0 1.5707963267948966" xyz="0 0 0" />
        <parent link="ur_flange" />
        <child link="ur_tool0" />
    </joint>
    <joint name="ur_robotiq_hande_base_joint" type="fixed">
        <parent link="ur_tool0" />
        <child link="ur_hand_e_link" />
        <origin rpy="0 0 0" xyz="0 0 0" />
    </joint>
    <link name="ur_hand_e_link">
        <inertial>
            <origin rpy="0 0 0" xyz="0 0 0.04607" />
            <mass value="0.86387" />
            <inertia ixx="1017560E-9" ixy="0" ixz="2235E-9" iyy="1028041E-9" iyz="0" izz="489810E-9" />
        </inertial>
        <visual>
            <origin rpy="0 0 0" xyz="0 0 0" />
            <geometry>
                <mesh filename="package://robotiq_description/meshes/hande/hand-e.dae"
                    scale="1.0 1.0 1.0" />
            </geometry>
            <material name="Dark">
                <color rgba=".1 0.1 0.1 1.0" />
            </material>
        </visual>
        <collision>
            <origin rpy="0 0 0" xyz="0 0 0" />
            <geometry>
                <mesh filename="package://robotiq_description/meshes/hande/hand-e-collision.dae"
                    scale="1.0 1.0 1.0" />
            </geometry>
        </collision>
    </link>
    <link name="ur_hande_left_finger">
        <inertial>
            <origin rpy="0 0 0" xyz="0.02262 -0.00759 0.00738" />
            <mass value="0.03804" />
            <inertia ixx="13567E-9" ixy="1849E-9" ixz="3622E-9" iyy="15784E-9" iyz="3616E-9"
                izz="7478E-9" />
        </inertial>
        <visual>
            <origin rpy="0 0 0" xyz="0 0 0" />
            <geometry>
                <mesh filename="package://robotiq_description/meshes/hande/finger_1.dae"
                    scale="1.0 1.0 1.0" />
            </geometry>
            <material name="DarkGray">
                <color rgba=".4 0.4 0.4 1.0" />
            </material>
        </visual>
        <collision>
            <origin rpy="0 0 0" xyz="0 0 0" />
            <geometry>
                <mesh filename="package://robotiq_description/meshes/hande/finger_1-collision.dae"
                    scale="1.0 1.0 1.0" />
            </geometry>
        </collision>
    </link>
    <link name="ur_hande_right_finger">
        <inertial>
            <origin rpy="0 0 0" xyz="-0.02262 0.00759 0.00738" />
            <mass value="0.03804" />
            <inertia ixx="13567E-9" ixy="1849E-9" ixz="-3622E-9" iyy="15784E-9" iyz="-3616E-9"
                izz="7478E-9" />
        </inertial>
        <visual>
            <origin rpy="0 0 0" xyz="0 0 0" />
            <geometry>
                <mesh filename="package://robotiq_description/meshes/hande/finger_2.dae"
                    scale="1.0 1.0 1.0" />
            </geometry>
            <material name="DarkGray">
                <color rgba=".4 0.4 0.4 1.0" />
            </material>
        </visual>
        <collision>
            <origin rpy="0 0 0" xyz="0 0 0" />
            <geometry>
                <mesh filename="package://robotiq_description/meshes/hande/finger_2-collision.dae"
                    scale="1.0 1.0 1.0" />
            </geometry>
        </collision>
    </link>
    <joint name="ur_hande_left_finger_joint" type="prismatic">
        <origin rpy="0 0 0" xyz="0 0 0.099" />
        <parent link="ur_hand_e_link" />
        <child link="ur_hande_left_finger" />
        <axis xyz="-1 0 0" />
        <limit effort="130" lower="0" upper="0.025" velocity="0.15" />
    </joint>
    <joint name="ur_hande_right_finger_joint" type="prismatic">
        <origin rpy="0 0 0" xyz="0 0 0.099" />
        <parent link="ur_hand_e_link" />
        <child link="ur_hande_right_finger" />
        <axis xyz="1 0 0" />
        <limit effort="130" lower="0" upper="0.025" velocity="0.15" />
        <mimic joint="ur_hande_left_finger_joint" multiplier="1" offset="0" />
    </joint>
    <!-- Improve grasping physics -->
    <!-- Mimic joints -->
    <link name="ur_ee_link">
        <inertial>
            <mass value="0.01" />
            <inertia ixx="0.0" ixy="0.0" ixz="0.0" iyy="0.0" iyz="0.0" izz="0.0" />
        </inertial>
    </link>
    <joint name="ur_ee_link_joint" type="fixed">
        <origin rpy="0 0 0" xyz="0 0 0.1365" />
        <parent link="ur_hand_e_link" />
        <child link="ur_ee_link" />
    </joint>
    <joint name="ur_base_joint" type="fixed">
        <origin rpy="0 0 0" xyz="0 0 0.005" />
        <parent link="mounting_base_link" />
        <child link="ur_base_link" />
    </joint>
</robot>